<?xml version="1.0" ?>
<sdf version="1.9">
  <world name="default">

    <plugin
      filename="gz-sim-physics-system"
      name="gz::sim::systems::Physics"/>

    <plugin
      filename="gz-sim-scene-broadcaster-system"
      name="gz::sim::systems::SceneBroadcaster"/>

    <light name="sun" type="directional">
      <pose>0 0 10 0 0 0</pose>
      <diffuse>0.8 0.8 0.8 1</diffuse>
      <specular>0.2 0.2 0.2 1</specular>
      <direction>-0.5 0.1 -0.9</direction>
    </light>

    <model name="ground_plane">
      <static>true</static>
      <link name="link">
        <collision name="collision">
          <geometry>
            <plane>
              <normal>0 0 1</normal>
              <size>100 100</size>
            </plane>
          </geometry>
        </collision>
        <visual name="visual">
          <geometry>
            <plane>
              <normal>0 0 1</normal>
              <size>100 100</size>
            </plane>
          </geometry>
        </visual>
      </link>
    </model>

    <model name="simple_motorcycle">
      <pose>0 0 0 0 0 0</pose>

      <link name="base_link">
        <pose>0 0 0.28 0 0 0</pose>

        <inertial>
          <mass>8.0</mass>
          <inertia>
            <ixx>0.2</ixx>
            <iyy>0.5</iyy>
            <izz>0.5</izz>
          </inertia>
        </inertial>

        <collision name="body_collision">
          <geometry>
            <box>
              <size>0.8 0.22 0.16</size>
            </box>
          </geometry>
        </collision>

        <visual name="body_visual">
          <geometry>
            <box>
              <size>0.8 0.22 0.16</size>
            </box>
          </geometry>
          <material>
            <diffuse>0.1 0.3 0.9 1</diffuse>
          </material>
        </visual>

        <visual name="handle_visual">
          <pose>0.35 0 0.22 0 0 0</pose>
          <geometry>
            <box>
              <size>0.08 0.5 0.04</size>
            </box>
          </geometry>
          <material>
            <diffuse>0.5 0.5 0.5 1</diffuse>
          </material>
        </visual>
      </link>

      <link name="left_wheel">
        <pose>-0.25 0.16 0.16 0 0 0</pose>

        <inertial>
          <mass>1.0</mass>
          <inertia>
            <ixx>0.01</ixx>
            <iyy>0.01</iyy>
            <izz>0.01</izz>
          </inertia>
        </inertial>

        <collision name="collision">
          <pose>0 0 0 1.5708 0 0</pose>
          <geometry>
            <cylinder>
              <radius>0.16</radius>
              <length>0.06</length>
            </cylinder>
          </geometry>
        </collision>

        <visual name="visual">
          <pose>0 0 0 1.5708 0 0</pose>
          <geometry>
            <cylinder>
              <radius>0.16</radius>
              <length>0.06</length>
            </cylinder>
          </geometry>
          <material>
            <diffuse>0.02 0.02 0.02 1</diffuse>
          </material>
        </visual>
      </link>

      <link name="right_wheel">
        <pose>-0.25 -0.16 0.16 0 0 0</pose>

        <inertial>
          <mass>1.0</mass>
          <inertia>
            <ixx>0.01</ixx>
            <iyy>0.01</iyy>
            <izz>0.01</izz>
          </inertia>
        </inertial>

        <collision name="collision">
          <pose>0 0 0 1.5708 0 0</pose>
          <geometry>
            <cylinder>
              <radius>0.16</radius>
              <length>0.06</length>
            </cylinder>
          </geometry>
        </collision>

        <visual name="visual">
          <pose>0 0 0 1.5708 0 0</pose>
          <geometry>
            <cylinder>
              <radius>0.16</radius>
              <length>0.06</length>
            </cylinder>
          </geometry>
          <material>
            <diffuse>0.02 0.02 0.02 1</diffuse>
          </material>
        </visual>
      </link>

      <link name="front_wheel">
        <pose>0.35 0 0.16 0 0 0</pose>

        <inertial>
          <mass>0.5</mass>
          <inertia>
            <ixx>0.005</ixx>
            <iyy>0.005</iyy>
            <izz>0.005</izz>
          </inertia>
        </inertial>

        <collision name="collision">
          <pose>0 0 0 1.5708 0 0</pose>
          <geometry>
            <cylinder>
              <radius>0.16</radius>
              <length>0.05</length>
            </cylinder>
          </geometry>
        </collision>

        <visual name="visual">
          <pose>0 0 0 1.5708 0 0</pose>
          <geometry>
            <cylinder>
              <radius>0.16</radius>
              <length>0.05</length>
            </cylinder>
          </geometry>
          <material>
            <diffuse>0.02 0.02 0.02 1</diffuse>
          </material>
        </visual>
      </link>

      <joint name="left_wheel_joint" type="revolute">
        <parent>base_link</parent>
        <child>left_wheel</child>
        <axis>
          <xyz>0 1 0</xyz>
        </axis>
      </joint>

      <joint name="right_wheel_joint" type="revolute">
        <parent>base_link</parent>
        <child>right_wheel</child>
        <axis>
          <xyz>0 1 0</xyz>
        </axis>
      </joint>

      <joint name="front_wheel_joint" type="fixed">
        <parent>base_link</parent>
        <child>front_wheel</child>
      </joint>

      <plugin
        filename="gz-sim-diff-drive-system"
        name="gz::sim::systems::DiffDrive">
        <left_joint>left_wheel_joint</left_joint>
        <right_joint>right_wheel_joint</right_joint>
        <wheel_separation>0.32</wheel_separation>
        <wheel_radius>0.16</wheel_radius>
        <topic>cmd_vel</topic>
        <odom_topic>odom</odom_topic>
        <frame_id>odom</frame_id>
        <child_frame_id>base_link</child_frame_id>
      </plugin>

    </model>
  </world>
</sdf>
